[2025-06-15 17:16:55,660] 79 root - INFO - Loading callbacks for model training...
[2025-06-15 17:16:55,660] 37 root - INFO - *******************
[2025-06-15 17:16:55,660] 38 root - INFO - >>>>>> stage Model Training started <<<<<<
[2025-06-15 17:16:55,662] 32 root - INFO - yaml file: config\config.yaml loaded successfully
[2025-06-15 17:16:55,677] 32 root - INFO - yaml file: params.yaml loaded successfully
[2025-06-15 17:16:55,678] 52 root - INFO - created directory at: artifacts
[2025-06-15 17:16:55,678] 52 root - INFO - created directory at: artifacts\training
[2025-06-15 17:16:55,871] 37 root - INFO - Creating validation and training data generators...
[2025-06-15 17:16:55,872] 43 root - ERROR - keras.preprocessing.image.ImageDataGenerator.flow_from_directory() got multiple values for keyword argument 'shuffle'
Traceback (most recent call last):
  File "E:\DL projects\Pneumonia-classification-projects\main.py", line 40, in <module>
    model_trainer.main()
  File "E:\DL projects\Pneumonia-classification-projects\src\pipeline\stage_03_model_training.py", line 20, in main
    training.train_valid_generator()
  File "E:\DL projects\Pneumonia-classification-projects\src\components\model_training.py", line 42, in train_valid_generator
    self.valid_generator = valid_datagenerator.flow_from_directory(
TypeError: keras.preprocessing.image.ImageDataGenerator.flow_from_directory() got multiple values for keyword argument 'shuffle'
