[2025-06-15 15:41:18,126] 23 root - INFO - 
****************************************
[2025-06-15 15:41:18,126] 24 root - INFO - >>>>>> Stage Prepare base model started <<<<<<
[2025-06-15 15:41:18,153] 32 root - INFO - yaml file: config\config.yaml loaded successfully
[2025-06-15 15:41:18,174] 32 root - INFO - yaml file: params.yaml loaded successfully
[2025-06-15 15:41:18,174] 52 root - INFO - created directory at: artifacts
[2025-06-15 15:41:18,174] 52 root - INFO - created directory at: artifacts/prepare_base_model
[2025-06-15 15:41:18,175] 29 root - ERROR - "'ConfigBox' object has no attribute 'image_size'"
Traceback (most recent call last):
  File "box\box.py", line 503, in box.box.Box.__getitem__
KeyError: 'IMAGE_SIZE'

The above exception was the direct cause of the following exception:

Traceback (most recent call last):
  File "box\box.py", line 536, in box.box.Box.__getattr__
  File "box\box.py", line 524, in box.box.Box.__getitem__
box.exceptions.BoxKeyError: "'IMAGE_SIZE'"

During handling of the above exception, another exception occurred:

Traceback (most recent call last):
  File "box\box.py", line 538, in box.box.Box.__getattr__
AttributeError: 'ConfigBox' object has no attribute 'IMAGE_SIZE'

The above exception was the direct cause of the following exception:

Traceback (most recent call last):
  File "box\config_box.py", line 28, in box.config_box.ConfigBox.__getattr__
  File "box\box.py", line 552, in box.box.Box.__getattr__
box.exceptions.BoxKeyError: "'ConfigBox' object has no attribute 'IMAGE_SIZE'"

During handling of the above exception, another exception occurred:

Traceback (most recent call last):
  File "box\box.py", line 503, in box.box.Box.__getitem__
KeyError: 'image_size'

The above exception was the direct cause of the following exception:

Traceback (most recent call last):
  File "box\box.py", line 536, in box.box.Box.__getattr__
  File "box\box.py", line 524, in box.box.Box.__getitem__
box.exceptions.BoxKeyError: "'image_size'"

During handling of the above exception, another exception occurred:

Traceback (most recent call last):
  File "box\box.py", line 538, in box.box.Box.__getattr__
AttributeError: 'ConfigBox' object has no attribute 'image_size'

The above exception was the direct cause of the following exception:

Traceback (most recent call last):
  File "E:\DL projects\Pneumonia-classification-projects\main.py", line 26, in <module>
    prepare_base_model.main()
  File "E:\DL projects\Pneumonia-classification-projects\src\pipeline\stage_02_prepare_base_model.py", line 13, in main
    prepare_base_model_config = config.get_prepare_base_model_config()
  File "E:\DL projects\Pneumonia-classification-projects\src\config\configuration.py", line 44, in get_prepare_base_model_config
    params_image_size=self.params.IMAGE_SIZE,
  File "box\config_box.py", line 30, in box.config_box.ConfigBox.__getattr__
  File "box\box.py", line 552, in box.box.Box.__getattr__
box.exceptions.BoxKeyError: "'ConfigBox' object has no attribute 'image_size'"
